Workbook

Sheet 설정
A1: 모찌 런처 — 밸런스 설정값
A2: 파란 글씨·노란 칸 = 수정 가능한 입력값. Firebase Remote Config 키와 1:1로 맞춰 두면 앱 업데이트 없이 튜닝 가능.
A4: 업그레이드 | B4: Remote Config 키 | C4: 기본 비용(씨앗) | D4: 비용 증가율 | E4: Lv당 효과 | F4: 효과 단위 | G4: 설명
A5: 고무줄 | B5: upg_launch | C5: 10 | D5: 1.15 | E5: 2.2 | F5: m/s 초기속도 | G5: 초기 발사 속도. 기본 15 m/s
A6: 공기역학 | B6: upg_aero | C6: 15 | D6: 1.17 | E6: 0.06 | F6: 비행거리 배율 | G6: Lv당 +6% 비행거리
A7: 부스터 | B7: upg_boost | C7: 25 | D7: 1.2 | E7: 1.3 | F7: 지수 | G7: 추가 거리 = 20 × Lv^지수 (m)
A8: 바운스 | B8: upg_bounce | C8: 40 | D8: 1.25 | E8: 0.04 | F8: 거리 배율 | G8: Lv당 +4% (튕김 횟수 증가 환산)
A9: 볼주머니 | B9: upg_coin | C9: 60 | D9: 1.3 | E9: 0.1 | F9: 씨앗 배율 | G9: Lv당 씨앗 획득 +10%
A11: 물리·보상 상수 | B11: 키 | C11: 값 | F11: 단위 | G11: 설명
A12: 기본 발사 속도 | B12: phys_v0 | C12: 15 | F12: m/s | G12: 고무줄 Lv0 속도
A13: 중력 | B13: phys_g | C13: 9.8 | F13: m/s² | G13: 거리 = v²/g 근사
A14: 부스터 계수 | B14: phys_boost_k | C14: 20 | F14: m | G14: 부스터 거리 계수
A15: m당 씨앗 | B15: coin_per_m | C15: 0.5 | F15: 씨앗/m | G15: 시뮬 기준 최적값(0.3=느림, 1.0=너무 빠름)
A16: 1판 평균 시간 | B16: run_sec | C16: 40 | F16: 초 | G16: 당기기~결과화면
A18: 구역 | B18: 시작 거리(m) | C18: 목표 도달 판수(광고X) | D18: 목표 도달 시간(분) | G18: 설계 의도
A19: 1. 뒷마당 | B19: 0 | C19: 1 | D19: =ROUND(C19*$C$16/60,0) -> 1 | G19: 튜토리얼
A20: 2. 공원 | B20: 500 | C20: 13 | D20: =ROUND(C20*$C$16/60,0) -> 9 | G20: 첫 10분 안에 첫 구역 돌파 → 몰입
A21: 3. 도시 옥상 | B21: 2000 | C21: 20 | D21: =ROUND(C21*$C$16/60,0) -> 13 | G21: 신규 장애물 등장
A22: 4. 구름 위 | B22: 6000 | C22: 29 | D22: =ROUND(C22*$C$16/60,0) -> 19 | G22: 카피바라 해금 — 중반 보상
A23: 5. 우주 | B23: 15000 | C23: 45 | D23: =ROUND(C23*$C$16/60,0) -> 30 | G23: 성장 둔화 구간 = 광고 2배·스타터팩 가치 극대화
A24: 6. 달 | B24: 40000 | C24: 113 | D24: =ROUND(C24*$C$16/60,0) -> 75 | G24: 프레스티지 해금 (하루 20~30분 플레이 시 3~5일차)
A26: ※ 목표 도달 판수는 tool/balance/pacing_sim.py 시뮬레이션(탐욕적 구매: 판 종료마다 씨앗 1개당 판당 씨앗 증가량이 가장 큰 업그레이드부터 반복 구매, 최선 항목이 부족하면 중단) 결과. 「진행 시뮬」 시트 참조.
A28: 체감 설정 (2.5D 샘플 HTML 기준) | B28: 키 | C28: 값 | D28: 단위 | E28: 설명
A29: 샘플 발사 속도(100%) | B29: feel_ref_v_px | C29: 1300 | D29: px/s | E29: 모찌 런처 2.5D.html V100. Lv0 화면 움직임을 샘플과 같게 맞추는 기준
A30: 샘플 중력 | B30: feel_ref_g_px | C30: 1400 | D30: px/s² | E30: 모찌 런처 2.5D.html GRAV
A31: 시뮬 시간 배율 | B31: sim_time_scale | C31: =ROUND(C30*C12/(C29*C13),4) -> 1.6484 | D31: 배 | E31: 계산식: 샘플g×v0 / (샘플v×g). 시뮬은 미터·실제 중력으로 계산하고(거리=공식 d), 이 배율로 빨리 재생해 샘플과 같은 체감 (ADR-012)
A32: 카메라 기본 배율 | B32: cam_base_px_per_m | C32: =ROUND(C29/(C12*C31),3) -> 52.576 | D32: px/m | E32: 계산식: 샘플v / (v0×시간배율). 가상 화면 높이 540 기준 Lv0 줌. 속도·고도에 따라 줌아웃
A34: 정확도 게이지·당기기 (GDD §2) | B34: 키 | C34: 값 | D34: 단위 | E34: 설명
A35: 최대 힘 | B35: gauge_max_power | C35: 1.1 | D35: 배 | E35: 힘 0~110%
A36: 바늘 기본 속도 | B36: gauge_speed_base | C36: 0.45 | D36: 트랙/초 | E36: p≤1: 0.45 + 1.35p
A37: 바늘 속도 계수 | B37: gauge_speed_k | C37: 1.35 | D37: 트랙/초 | E37: p≤1 기울기
A38: 과충전 가속 | B38: gauge_over_k | C38: 9 | D38: 배 | E38: p>1: 1.8 × (1 + 9(p−1))
A39: PERFECT 폭 | B39: gauge_zone_width | C39: 0.1 | D39: off | E39: 가운데에서 벗어난 정도 off ≤ 0.1 (트랙 0.45~0.55)
A40: GREAT 경계 | B40: gauge_great_off | C40: 0.3 | D40: off | E40: off ≤ 0.3 (트랙 0.35~0.65)
A41: GOOD 경계 | B41: gauge_good_off | C41: 0.6 | D41: off | E41: off ≤ 0.6 (트랙 0.20~0.80), 나머지 아쉬워요
A42: PERFECT 배율 | B42: gauge_perfect_mult | C42: 1.15 | D42: 배
A43: GREAT 최소 배율 | B43: gauge_great_mult_min | C43: 1.03 | D43: 배 | E43: 구간 바깥 경계 값. 안쪽 경계로 갈수록 최대까지 선형 보간
A44: GREAT 최대 배율 | B44: gauge_great_mult_max | C44: 1.13 | D44: 배 | E44: GDD 표 ×1.03~1.13 (ADR-013, 샘플은 1.097 까지만)
A45: GOOD 최소 배율 | B45: gauge_good_mult_min | C45: 0.95 | D45: 배
A46: GOOD 최대 배율 | B46: gauge_good_mult_max | C46: 1.03 | D46: 배
...

Sheet 업그레이드표
A1: 레벨별 비용·효과 (설정 시트 값으로 자동 계산)
A3: Lv | B3: 고무줄 비용 | C3: 공기역학 비용 | D3: 부스터 비용 | E3: 바운스 비용 | F3: 볼주머니 비용 | G3: 발사속도(m/s) | H3: 공기역학 배율 | I3: 부스터 거리(m) | J3: 바운스 배율 | K3: 씨앗 배율 | L3: 예상 거리(m) (전 항목 동일 Lv)
A4: 0 | B4: =ROUND(설정!$C$5*설정!$D$5^$A4,0) -> 10 | C4: =ROUND(설정!$C$6*설정!$D$6^$A4,0) -> 15 | D4: =ROUND(설정!$C$7*설정!$D$7^$A4,0) -> 25 | E4: =ROUND(설정!$C$8*설정!$D$8^$A4,0) -> 40 | F4: =ROUND(설정!$C$9*설정!$D$9^$A4,0) -> 60 | G4: =설정!$C$12+설정!$E$5*A4 -> 15 | H4: =1+설정!$E$6*A4 -> 1 | I4: =설정!$C$14*A4^설정!$E$7 -> 0 | J4: =1+설정!$E$8*A4 -> 1 | K4: =1+설정!$E$9*A4 -> 1 | L4: =(G4^2/설정!$C$13*H4+I4)*J4 -> 22.959184
A5: 1 | B5: =ROUND(설정!$C$5*설정!$D$5^$A5,0) -> 12 | C5: =ROUND(설정!$C$6*설정!$D$6^$A5,0) -> 18 | D5: =ROUND(설정!$C$7*설정!$D$7^$A5,0) -> 30 | E5: =ROUND(설정!$C$8*설정!$D$8^$A5,0) -> 50 | F5: =ROUND(설정!$C$9*설정!$D$9^$A5,0) -> 78 | G5: =설정!$C$12+설정!$E$5*A5 -> 17.2 | H5: =1+설정!$E$6*A5 -> 1.06 | I5: =설정!$C$14*A5^설정!$E$7 -> 20 | J5: =1+설정!$E$8*A5 -> 1.04 | K5: =1+설정!$E$9*A5 -> 1.1 | L5: =(G5^2/설정!$C$13*H5+I5)*J5 -> 54.078981
A6: 2 | B6: =ROUND(설정!$C$5*설정!$D$5^$A6,0) -> 13 | C6: =ROUND(설정!$C$6*설정!$D$6^$A6,0) -> 21 | D6: =ROUND(설정!$C$7*설정!$D$7^$A6,0) -> 36 | E6: =ROUND(설정!$C$8*설정!$D$8^$A6,0) -> 63 | F6: =ROUND(설정!$C$9*설정!$D$9^$A6,0) -> 101 | G6: =설정!$C$12+설정!$E$5*A6 -> 19.4 | H6: =1+설정!$E$6*A6 -> 1.12 | I6: =설정!$C$14*A6^설정!$E$7 -> 49.245777 | J6: =1+설정!$E$8*A6 -> 1.08 | K6: =1+설정!$E$9*A6 -> 1.2 | L6: =(G6^2/설정!$C$13*H6+I6)*J6 -> 99.639016
A7: 3 | B7: =ROUND(설정!$C$5*설정!$D$5^$A7,0) -> 15 | C7: =ROUND(설정!$C$6*설정!$D$6^$A7,0) -> 24 | D7: =ROUND(설정!$C$7*설정!$D$7^$A7,0) -> 43 | E7: =ROUND(설정!$C$8*설정!$D$8^$A7,0) -> 78 | F7: =ROUND(설정!$C$9*설정!$D$9^$A7,0) -> 132 | G7: =설정!$C$12+설정!$E$5*A7 -> 21.6 | H7: =1+설정!$E$6*A7 -> 1.18 | I7: =설정!$C$14*A7^설정!$E$7 -> 83.42335 | J7: =1+설정!$E$8*A7 -> 1.12 | K7: =1+설정!$E$9*A7 -> 1.3 | L7: =(G7^2/설정!$C$13*H7+I7)*J7 -> 156.3531
A8: 4 | B8: =ROUND(설정!$C$5*설정!$D$5^$A8,0) -> 17 | C8: =ROUND(설정!$C$6*설정!$D$6^$A8,0) -> 28 | D8: =ROUND(설정!$C$7*설정!$D$7^$A8,0) -> 52 | E8: =ROUND(설정!$C$8*설정!$D$8^$A8,0) -> 98 | F8: =ROUND(설정!$C$9*설정!$D$9^$A8,0) -> 171 | G8: =설정!$C$12+설정!$E$5*A8 -> 23.8 | H8: =1+설정!$E$6*A8 -> 1.24 | I8: =설정!$C$14*A8^설정!$E$7 -> 121.25733 | J8: =1+설정!$E$8*A8 -> 1.16 | K8: =1+설정!$E$9*A8 -> 1.4 | L8: =(G8^2/설정!$C$13*H8+I8)*J8 -> 223.79802
A9: 5 | B9: =ROUND(설정!$C$5*설정!$D$5^$A9,0) -> 20 | C9: =ROUND(설정!$C$6*설정!$D$6^$A9,0) -> 33 | D9: =ROUND(설정!$C$7*설정!$D$7^$A9,0) -> 62 | E9: =ROUND(설정!$C$8*설정!$D$8^$A9,0) -> 122 | F9: =ROUND(설정!$C$9*설정!$D$9^$A9,0) -> 223 | G9: =설정!$C$12+설정!$E$5*A9 -> 26 | H9: =1+설정!$E$6*A9 -> 1.3 | I9: =설정!$C$14*A9^설정!$E$7 -> 162.06566 | J9: =1+설정!$E$8*A9 -> 1.2 | K9: =1+설정!$E$9*A9 -> 1.5 | L9: =(G9^2/설정!$C$13*H9+I9)*J9 -> 302.08695
A10: 6 | B10: =ROUND(설정!$C$5*설정!$D$5^$A10,0) -> 23 | C10: =ROUND(설정!$C$6*설정!$D$6^$A10,0) -> 38 | D10: =ROUND(설정!$C$7*설정!$D$7^$A10,0) -> 75 | E10: =ROUND(설정!$C$8*설정!$D$8^$A10,0) -> 153 | F10: =ROUND(설정!$C$9*설정!$D$9^$A10,0) -> 290 | G10: =설정!$C$12+설정!$E$5*A10 -> 28.2 | H10: =1+설정!$E$6*A10 -> 1.36 | I10: =설정!$C$14*A10^설정!$E$7 -> 205.41238 | J10: =1+설정!$E$8*A10 -> 1.24 | K10: =1+설정!$E$9*A10 -> 1.6 | L10: =(G10^2/설정!$C$13*H10+I10)*J10 -> 391.55755
A11: 7 | B11: =ROUND(설정!$C$5*설정!$D$5^$A11,0) -> 27 | C11: =ROUND(설정!$C$6*설정!$D$6^$A11,0) -> 45 | D11: =ROUND(설정!$C$7*설정!$D$7^$A11,0) -> 90 | E11: =ROUND(설정!$C$8*설정!$D$8^$A11,0) -> 191 | F11: =ROUND(설정!$C$9*설정!$D$9^$A11,0) -> 376 | G11: =설정!$C$12+설정!$E$5*A11 -> 30.4 | H11: =1+설정!$E$6*A11 -> 1.42 | I11: =설정!$C$14*A11^설정!$E$7 -> 250.99059 | J11: =1+설정!$E$8*A11 -> 1.28 | K11: =1+설정!$E$9*A11 -> 1.7 | L11: =(G11^2/설정!$C$13*H11+I11)*J11 -> 492.67135
A12: 8 | B12: =ROUND(설정!$C$5*설정!$D$5^$A12,0) -> 31 | C12: =ROUND(설정!$C$6*설정!$D$6^$A12,0) -> 53 | D12: =ROUND(설정!$C$7*설정!$D$7^$A12,0) -> 107 | E12: =ROUND(설정!$C$8*설정!$D$8^$A12,0) -> 238 | F12: =ROUND(설정!$C$9*설정!$D$9^$A12,0) -> 489 | G12: =설정!$C$12+설정!$E$5*A12 -> 32.6 | H12: =1+설정!$E$6*A12 -> 1.48 | I12: =설정!$C$14*A12^설정!$E$7 -> 298.57056 | J12: =1+설정!$E$8*A12 -> 1.32 | K12: =1+설정!$E$9*A12 -> 1.8 | L12: =(G12^2/설정!$C$13*H12+I12)*J12 -> 605.97109
A13: 9 | B13: =ROUND(설정!$C$5*설정!$D$5^$A13,0) -> 35 | C13: =ROUND(설정!$C$6*설정!$D$6^$A13,0) -> 62 | D13: =ROUND(설정!$C$7*설정!$D$7^$A13,0) -> 129 | E13: =ROUND(설정!$C$8*설정!$D$8^$A13,0) -> 298 | F13: =ROUND(설정!$C$9*설정!$D$9^$A13,0) -> 636 | G13: =설정!$C$12+설정!$E$5*A13 -> 34.8 | H13: =1+설정!$E$6*A13 -> 1.54 | I13: =설정!$C$14*A13^설정!$E$7 -> 347.97277 | J13: =1+설정!$E$8*A13 -> 1.36 | K13: =1+설정!$E$9*A13 -> 1.9 | L13: =(G13^2/설정!$C$13*H13+I13)*J13 -> 732.05951
A14: 10 | B14: =ROUND(설정!$C$5*설정!$D$5^$A14,0) -> 40 | C14: =ROUND(설정!$C$6*설정!$D$6^$A14,0) -> 72 | D14: =ROUND(설정!$C$7*설정!$D$7^$A14,0) -> 155 | E14: =ROUND(설정!$C$8*설정!$D$8^$A14,0) -> 373 | F14: =ROUND(설정!$C$9*설정!$D$9^$A14,0) -> 827 | G14: =설정!$C$12+설정!$E$5*A14 -> 37 | H14: =1+설정!$E$6*A14 -> 1.6 | I14: =설정!$C$14*A14^설정!$E$7 -> 399.05246 | J14: =1+설정!$E$8*A14 -> 1.4 | K14: =1+설정!$E$9*A14 -> 2 | L14: =(G14^2/설정!$C$13*H14+I14)*J14 -> 871.58773
A15: 11 | B15: =ROUND(설정!$C$5*설정!$D$5^$A15,0) -> 47 | C15: =ROUND(설정!$C$6*설정!$D$6^$A15,0) -> 84 | D15: =ROUND(설정!$C$7*설정!$D$7^$A15,0) -> 186 | E15: =ROUND(설정!$C$8*설정!$D$8^$A15,0) -> 466 | F15: =ROUND(설정!$C$9*설정!$D$9^$A15,0) -> 1075 | G15: =설정!$C$12+설정!$E$5*A15 -> 39.2 | H15: =1+설정!$E$6*A15 -> 1.66 | I15: =설정!$C$14*A15^설정!$E$7 -> 451.69001 | J15: =1+설정!$E$8*A15 -> 1.44 | K15: =1+설정!$E$9*A15 -> 2.1 | L15: =(G15^2/설정!$C$13*H15+I15)*J15 -> 1025.2483
... A84: 80 | B84: =ROUND(설정!$C$5*설정!$D$5^$A84,0) -> 717509 | C84: =ROUND(설정!$C$6*설정!$D$6^$A84,0) -> 4275237 | D84: =ROUND(설정!$C$7*설정!$D$7^$A84,0) -> 54005712 | E84: =ROUND(설정!$C$8*설정!$D$8^$A84,0) -> 2263919770 | F84: =ROUND(설정!$C$9*설정!$D$9^$A84,0) -> 78274343703 | G84: =설정!$C$12+설정!$E$5*A84 -> 191 | H84: =1+설정!$E$6*A84 -> 5.8 | I84: =설정!$C$14*A84^설정!$E$7 -> 5957.2658 | J84: =1+설정!$E$8*A84 -> 4.2 | K84: =1+설정!$E$9*A84 -> 9 | L84: =(G84^2/설정!$C$13*H84+I84)*J84 -> 115701.86

Sheet 진행 시뮬
A1: 판별 진행 시뮬레이션 — 광고 시청률 3개 시나리오
A2: tool/balance/pacing_sim.py 생성값(수식 아님). 설정 변경 시 export_balance.py → pacing_sim.py 재실행. 구매 규칙: 판 종료마다 '씨앗 1개당 판당 씨앗 증가량' 최대 업그레이드를 반복 구매, 최선 항목이 부족하면 중단. 비용 ROUND(사사오입). 광고 30% = 매판 씨앗 ×1.3(기대값), 광고 100% = ×2.
A4: 판 | B4: 누적 시간(분) | C4: 거리 — 광고X | D4: 거리 — 광고 30% | E4: 거리 — 광고 100% | F4: 씨앗 — 광고X | G4: 씨앗 — 광고 100% | H4: 광고X 판당 성장률 | I4: 고무줄 | J4: 공기역학 | K4: 부스터 | L4: 바운스 | M4: 볼주머니
A5: 1 | B5: =ROUND(A5*설정!$C$16/60,1) -> 0.7 | C5: 23 | D5: 23 | E5: 23 | F5: 11 | G5: 23 | H5: 0 | I5: 0 | J5: 0 | K5: 0 | L5: 0 | M5: 0
A6: 2 | B6: =ROUND(A6*설정!$C$16/60,1) -> 1.3 | C6: 23 | D6: 23 | E6: 23 | F6: 11 | G6: 23 | H6: =IF(C5>0,C6/C5-1,0) -> 0 | I6: 0 | J6: 0 | K6: 0 | L6: 0 | M6: 0
A7: 3 | B7: =ROUND(A7*설정!$C$16/60,1) -> 2 | C7: 23 | D7: 43 | E7: 43 | F7: 11 | G7: 43 | H7: =IF(C6>0,C7/C6-1,0) -> 0 | I7: 0 | J7: 0 | K7: 1 | L7: 0 | M7: 0
A8: 4 | B8: =ROUND(A8*설정!$C$16/60,1) -> 2.7 | C8: 43 | D8: 72 | E8: 72 | F8: 21 | G8: 72 | H8: =IF(C7>0,C8/C7-1,0) -> 0.86956522 | I8: 0 | J8: 0 | K8: 2 | L8: 0 | M8: 0
A9: 5 | B9: =ROUND(A9*설정!$C$16/60,1) -> 3.3 | C9: 72 | D9: 106 | E9: 144 | F9: 36 | G9: 144 | H9: =IF(C8>0,C9/C8-1,0) -> 0.6744186 | I9: 0 | J9: 0 | K9: 3 | L9: 0 | M9: 0
A10: 6 | B10: =ROUND(A10*설정!$C$16/60,1) -> 4 | C10: 106 | D10: 144 | E10: 263 | F10: 53 | G10: 263 | H10: =IF(C9>0,C10/C9-1,0) -> 0.47222222 | I10: 0 | J10: 0 | K10: 4 | L10: 0 | M10: 0
A11: 7 | B11: =ROUND(A11*설정!$C$16/60,1) -> 4.7 | C11: 144 | D11: 236 | E11: 345 | F11: 72 | G11: 380 | H11: =IF(C10>0,C11/C10-1,0) -> 0.35849057 | I11: 1 | J11: 0 | K11: 5 | L11: 0 | M11: 0
A12: 8 | B12: =ROUND(A12*설정!$C$16/60,1) -> 5.3 | C12: 192 | D12: 332 | E12: 493 | F12: 96 | G12: 592 | H12: =IF(C11>0,C12/C11-1,0) -> 0.33333333 | I12: 4 | J12: 0 | K12: 6 | L12: 0 | M12: 0
A13: 9 | B13: =ROUND(A13*설정!$C$16/60,1) -> 6 | C13: 263 | D13: 407 | E13: 731 | F13: 132 | G13: 951 | H13: =IF(C12>0,C13/C12-1,0) -> 0.36979167 | I13: 7 | J13: 0 | K13: 7 | L13: 0 | M13: 0
A14: 10 | B14: =ROUND(A14*설정!$C$16/60,1) -> 6.7 | C14: 345 | D14: 493 | E14: 1005 | F14: 173 | G14: 1507 | H14: =IF(C13>0,C14/C13-1,0) -> 0.31178707 | I14: 8 | J14: 0 | K14: 8 | L14: 0 | M14: 1
A15: 11 | B15: =ROUND(A15*설정!$C$16/60,1) -> 7.3 | C15: 407 | D15: 648 | E15: 1442 | F15: 224 | G15: 2308 | H15: =IF(C14>0,C15/C14-1,0) -> 0.17971014 | I15: 11 | J15: 2 | K15: 8 | L15: 0 | M15: 2
A16: 12 | B16: =ROUND(A16*설정!$C$16/60,1) -> 8 | C16: 474 | D16: 821 | E16: 1955 | F16: 285 | G16: 3519 | H16: =IF(C15>0,C16/C15-1,0) -> 0.16461916 | I16: 12 | J16: 3 | K16: 9 | L16: 1 | M16: 2
A17: 13 | B17: =ROUND(A17*설정!$C$16/60,1) -> 8.7 | C17: 577 | D17: 1046 | E17: 2690 | F17: 346 | G17: 5111 | H17: =IF(C16>0,C17/C16-1,0) -> 0.21729958 | I17: 14 | J17: 5 | K17: 9 | L17: 2 | M17: 3
... A27: 23 | B27: =ROUND(A27*설정!$C$16/60,1) -> 15.3 | C27: 3268 | D27: 6125 | E27: 12694 | F27: 3431 | G27: 38082 | H27: =IF(C26>0,C27/C26-1,0) -> 0.14586255 | I27: 32 | J27: 21 | K27: 18 | L27: 13 | M27: 11
A28: 24 | B28: =ROUND(A28*설정!$C$16/60,1) -> 16 | C28: 3859 | D28: 7015 | E28: 13930 | F28: 4052 | G28: 43183 | H28: =IF(C27>0,C28/C27-1,0) -> 0.18084455 | I28: 33 | J28: 23 | K28: 18 | L28: 14 | M28: 12 | O28: 구역 도달 판수
A29: 25 | B29: =ROUND(A29*설정!$C$16/60,1) -> 16.7 | C29: 4244 | D29: 7639 | E29: 14804 | F29: 4668 | G29: 47373 | H29: =IF(C28>0,C29/C28-1,0) -> 0.099766779 | I29: 35 | J29: 24 | K29: 19 | L29: 14 | M29: 13 | O29: 구역 | P29: 광고X | Q29: 광고 30% | R29: 광고 100%
A30: 26 | B30: =ROUND(A30*설정!$C$16/60,1) -> 17.3 | C30: 4721 | D30: 8362 | E30: 15869 | F30: 5430 | G30: 50781 | H30: =IF(C29>0,C30/C29-1,0) -> 0.11239397 | I30: 36 | J30: 25 | K30: 20 | L30: 15 | M30: 14 | O30: 1. 뒷마당 | P30: 1 | Q30: 1 | R30: 1
A31: 27 | B31: =ROUND(A31*설정!$C$16/60,1) -> 18 | C31: 5194 | D31: 9068 | E31: 16760 | F31: 6233 | G31: 55308 | H31: =IF(C30>0,C31/C30-1,0) -> 0.10019064 | I31: 37 | J31: 27 | K31: 21 | L31: 16 | M31: 14 | O31: 2. 공원 | P31: 13 | Q31: 11 | R31: 9
A32: 28 | B32: =ROUND(A32*설정!$C$16/60,1) -> 18.7 | C32: 5791 | D32: 9834 | E32: 17819 | F32: 6950 | G32: 58803 | H32: =IF(C31>0,C32/C31-1,0) -> 0.11494032 | I32: 39 | J32: 27 | K32: 21 | L32: 17 | M32: 15 | O32: 3. 도시 옥상 | P32: 20 | Q32: 16 | R32: 13
A33: 29 | B33: =ROUND(A33*설정!$C$16/60,1) -> 19.3 | C33: 6322 | D33: 10472 | E33: 18629 | F33: 7903 | G33: 63339 | H33: =IF(C32>0,C33/C32-1,0) -> 0.091694008 | I33: 40 | J33: 29 | K33: 22 | L33: 18 | M33: 15 | O33: 4. 구름 위 | P33: 29 | Q33: 23 | R33: 17
A34: 30 | B34: =ROUND(A34*설정!$C$16/60,1) -> 20 | C34: 7015 | D34: 11227 | E34: 19884 | F34: 8769 | G34: 67607 | H34: =IF(C33>0,C34/C33-1,0) -> 0.10961721 | I34: 41 | J34: 30 | K34: 23 | L34: 18 | M34: 16 | O34: 5. 우주 | P34: 45 | Q34: 36 | R34: 26
A35: 31 | B35: =ROUND(A35*설정!$C$16/60,1) -> 20.7 | C35: 7465 | D35: 11791 | E35: 20145 | F35: 9705 | G35: 70508 | H35: =IF(C34>0,C35/C34-1,0) -> 0.064148254 | I35: 42 | J35: 31 | K35: 23 | L35: 19 | M35: 17 | O35: 6. 달 | P35: 113 | Q35: 88 | R35: 60
A36: 32 | B36: =ROUND(A36*설정!$C$16/60,1) -> 21.3 | C36: 7999 | D36: 12694 | E36: 21607 | F36: 10798 | G36: 75624 | H36: =IF(C35>0,C36/C35-1,0) -> 0.071533825 | I36: 43 | J36: 32 | K36: 24 | L36: 20 | M36: 17
A37: 33 | B37: =ROUND(A37*설정!$C$16/60,1) -> 22 | C37: 8684 | D37: 13372 | E37: 22007 | F37: 11724 | G37: 79225 | H37: =IF(C36>0,C37/C36-1,0) -> 0.085635704 | I37: 44 | J37: 32 | K37: 25 | L37: 20 | M37: 18 | O37: → 광고를 매판 보면 달 도달이 약 47% 빨라짐(113→60판). 광고 가치가 체감되는 격차.
A38: 34 | B38: =ROUND(A38*설정!$C$16/60,1) -> 22.7 | C38: 9068 | D38: 14214 | E38: 23005 | F38: 12695 | G38: 82819 | H38: =IF(C37>0,C38/C37-1,0) -> 0.044219254 | I38: 45 | J38: 34 | K38: 25 | L38: 21 | M38: 18
A39: 35 | B39: =ROUND(A39*설정!$C$16/60,1) -> 23.3 | C39: 9834 | D39: 14599 | E39: 24298 | F39: 13768 | G39: 87472 | H39: =IF(C38>0,C39/C38-1,0) -> 0.084472872 | I39: 46 | J39: 34 | K39: 26 | L39: 21 | M39: 19
A40: 36 | B40: =ROUND(A40*설정!$C$16/60,1) -> 24 | C40: 10250 | D40: 15247 | E40: 24298 | F40: 14862 | G40: 89902 | H40: =IF(C39>0,C40/C39-1,0) -> 0.042302217 | I40: 47 | J40: 35 | K40: 26 | L40: 22 | M40: 19
A41: 37 | B41: =ROUND(A41*설정!$C$16/60,1) -> 24.7 | C41: 10935 | D41: 15869 | E41: 25369 | F41: 15856 | G41: 93864 | H41: =IF(C40>0,C41/C40-1,0) -> 0.066829268 | I41: 48 | J41: 36 | K41: 27 | L41: 22 | M41: 19
A42: 38 | B42: =ROUND(A42*설정!$C$16/60,1) -> 25.3 | C42: 11546 | D42: 16760 | E42: 26437 | F42: 16741 | G42: 97816 | H42: =IF(C41>0,C42/C41-1,0) -> 0.055875629 | I42: 48 | J42: 36 | K42: 27 | L42: 23 | M42: 20
A43: 39 | B43: =ROUND(A43*설정!$C$16/60,1) -> 26 | C43: 11791 | D43: 17431 | E43: 26940 | F43: 17687 | G43: 102374 | H43: =IF(C42>0,C43/C42-1,0) -> 0.02121947 | I43: 49 | J43: 37 | K43: 28 | L43: 24 | M43: 20
A44: 40 | B44: =ROUND(A44*설정!$C$16/60,1) -> 26.7 | C44: 12694 | D44: 17819 | E44: 27574 | F44: 19041 | G44: 104781 | H44: =IF(C43>0,C44/C43-1,0) -> 0.076583835 | I44: 50 | J44: 37 | K44: 28 | L44: 24 | M44: 20
A45: 41 | B45: =ROUND(A45*설정!$C$16/60,1) -> 27.3 | C45: 13045 | D45: 18629 | E45: 28402 | F45: 19568 | G45: 107929 | H45: =IF(C44>0,C45/C44-1,0) -> 0.027650859 | I45: 50 | J45: 38 | K45: 29 | L45: 24 | M45: 21
A46: 42 | B46: =ROUND(A46*설정!$C$16/60,1) -> 28 | C46: 13372 | D46: 19360 | E46: 29245 | F46: 20726 | G46: 111131 | H46: =IF(C45>0,C46/C45-1,0) -> 0.025067076 | I46: 51 | J46: 39 | K46: 29 | L46: 25 | M46: 21
A47: 43 | B47: =ROUND(A47*설정!$C$16/60,1) -> 28.7 | C47: 14214 | D47: 19884 | E47: 29749 | F47: 22032 | G47: 116022 | H47: =IF(C46>0,C47/C46-1,0) -> 0.062967395 | I47: 52 | J47: 39 | K47: 29 | L47: 25 | M47: 22
A48: 44 | B48: =ROUND(A48*설정!$C$16/60,1) -> 29.3 | C48: 14599 | D48: 20145 | E48: 30804 | F48: 23358 | G48: 120137 | H48: =IF(C47>0,C48/C47-1,0) -> 0.027085972 | I48: 52 | J48: 40 | K48: 30 | L48: 26 | M48: 22
A49: 45 | B49: =ROUND(A49*설정!$C$16/60,1) -> 30 | C49: 15247 | D49: 20814 | E49: 31359 | F49: 24394 | G49: 122299 | H49: =IF(C48>0,C49/C48-1,0) -> 0.044386602 | I49: 53 | J49: 41 | K49: 30 | L49: 26 | M49: 22
... A304: 300 | B304: =ROUND(A304*설정!$C$16/60,1) -> 200 | C304: 73277 | D304: 82787 | E304: 99630 | F304: 179527 | G304: 538000 | H304: =IF(C303>0,C304/C303-1,0) -> 0 | I304: 86 | J304: 70 | K304: 51 | L304: 47 | M304: 39

Sheet 수익 추정
A1: 수익 추정 (입력값 변경 시 자동 계산)
A3: 항목 | B3: 값 | C3: 단위 | D3: 근거/메모
A4: DAU | B4: 10000 | C4: 명 | D4: 가정 — 소프트런칭 후 목표치로 교체
A5: 보상형 광고 시청/DAU | B5: 3 | C5: 회/일 | D5: 설계 목표 (결과 2배·부스트·오프라인 2배)
A6: 보상형 eCPM | B6: 10 | C6: USD | D6: 가정 — 국가/메디에이션에 따라 큰 편차, 실측으로 교체
A7: 전면 광고 노출/DAU | B7: 4 | C7: 회/일 | D7: 3~4판마다 1회, 첫 5판 제외
A8: 전면 eCPM | B8: 6 | C8: USD | D8: 가정
A9: 광고 제거 구매 비율(전면 제거) | B9: 0.01 | C9: DAU 대비 누적 | D9: 가정
A10: IAP 결제 전환율 | B10: 0.01 | C10: 일간 DAU 대비 | D10: 가정 — 하이브리드 캐주얼 일반 범위
A11: 결제자 평균 결제액(ARPPU) | B11: 3 | C11: USD | D11: 스타터팩·코인팩 혼합 가정
A12: 스토어 수수료 | B12: 0.15 | D12: Google Play 소규모 사업자 15% 구간
A13: 환율 | B13: 1380 | C13: KRW/USD | D13: 가정 — 실제 환율로 교체
A15: 계산 | B15: 일 수익(USD) | C15: 월 수익(USD) | D15: 월 수익(KRW)
A16: 보상형 광고 | B16: =B4*B5*B6/1000 -> 300 | C16: =B16*30 -> 9000 | D16: =C16*$B$13 -> 12420000
A17: 전면 광고 | B17: =B4*(1-B9)*B7*B8/1000 -> 237.6 | C17: =B17*30 -> 7128 | D17: =C17*$B$13 -> 9836640
A18: IAP(수수료 차감) | B18: =B4*B10*B11*(1-B12) -> 255 | C18: =B18*30 -> 7650 | D18: =C18*$B$13 -> 10557000
A19: 합계 | B19: =SUM(B16:B18) -> 792.6 | C19: =SUM(C16:C18) -> 23778 | D19: =SUM(D16:D18) -> 32813640
A20: 광고 비중 | B20: =IF(B19>0,(B16+B17)/B19,0) -> 0.67827403
A21: ARPDAU | B21: =IF(B4>0,B19/B4,0) -> 0.07926
A23: ※ 모든 입력값은 가정치입니다. 소프트런칭 후 AdMob·Play Console 실측값으로 교체하세요.

Sheet 별사탕 경제
A1: 별사탕(하드 화폐) 주간 수급 — 무과금 기준
A3: 획득처 | B3: 횟수/주 | C3: 1회 보상 | D3: 주간 획득 | E3: 메모
A4: 일일 미션 (3개 × 10) | B4: 7 | C4: 30 | D4: =B4*C4 -> 210 | E4: 매일 완료 가정
A5: 일일 미션 전부 완료 보너스 | B5: 7 | C5: 20 | D5: =B5*C5 -> 140
A6: 7일 출석 (합계 환산) | B6: 1 | C6: 100 | D6: =B6*C6 -> 100 | E6: 7일째 한정 스킨 별도
A7: 업적 (주 평균) | B7: 3 | C7: 20 | D7: =B7*C7 -> 60 | E7: 초반 많고 후반 감소
A8: 보물 상자 이벤트 | B8: 5 | C8: 5 | D8: =B8*C8 -> 25 | E8: 판당 약 10% 중 일부
A9: 주간 합계 | D9: =SUM(D4:D8) -> 535
A11: 소비처 | B11: 가격(별사탕) | D11: 주간 가능 횟수 | E11: 메모
A12: 뽑기 1회 | B12: 100 | D12: =ROUND($D$9/B12,1) -> 5.4 | E12: 목표: 무과금 주 3~5회
A13: 스킨 1개 | B13: 300 | D13: =ROUND($D$9/B13,1) -> 1.8
A14: 부활 1회 | B14: 20 | D14: =ROUND($D$9/B14,1) -> 26.8
A15: 마을 꾸미기 1개 | B15: 150 | D15: =ROUND($D$9/B15,1) -> 3.6
A17: 인앱 상품 | B17: 가격(KRW) | C17: 별사탕 | D17: 별사탕 100개당 가격(KRW) | E17: 무과금 주간 획득량 대비
A18: 별사탕 소 | B18: 1200 | C18: 100 | D18: =ROUND(B18/C18*100,0) -> 1200 | E18: =C18/$D$9 -> 0.18691589
A19: 별사탕 중 | B19: 5900 | C19: 550 | D19: =ROUND(B19/C19*100,0) -> 1073 | E19: =C19/$D$9 -> 1.0280374
A20: 별사탕 대 | B20: 29000 | C20: 3000 | D20: =ROUND(B20/C20*100,0) -> 967 | E20: =C20/$D$9 -> 5.6074766
A21: 광고 제거(보너스) | B21: 5900 | C21: 300 | D21: =ROUND(B21/C21*100,0) -> 1967 | E21: =C21/$D$9 -> 0.56074766
A22: 스타터팩(보너스) | B22: 2500 | C22: 500 | D22: =ROUND(B22/C22*100,0) -> 500 | E22: =C22/$D$9 -> 0.93457944
A23: 월정액(30일) | B23: 4400 | C23: 1500 | D23: =ROUND(B23/C23*100,0) -> 293 | E23: =C23/$D$9 -> 2.8037383
A25: ※ 월정액은 매일 50 × 30일 = 1,500으로 환산. 스타터팩·월정액의 100개당 가격이 가장 낮아야 첫 결제 전환에 유리.

Sheet 햄스터 마을
A1: 햄스터 마을 오프라인 생산
A2: 시간당 생산 = 최고기록 1판 씨앗 × 기본비율 × (1 + 친구보너스 × 친구 수) × (1 + 쳇바퀴보너스 × 쳇바퀴 Lv)
A4: 파라미터 | B4: 값 | C4: Remote Config 키
A5: 기본 비율 | B5: 0.2 | C5: village_base_ratio
A6: 친구 1마리당 보너스 | B6: 0.15 | C6: village_friend_bonus
A7: 쳇바퀴 Lv당 보너스 | B7: 0.1 | C7: village_wheel_bonus
A8: 기본 저장 한도(시간) | B8: 8 | C8: village_cap_hours
A9: 광고 시청 배율 | B9: 2 | C9: village_ad_mult
A11: 시점(구역 도달) | B11: 최고기록 1판 씨앗 | C11: 친구 수 | D11: 쳇바퀴 Lv | E11: 시간당 생산 | F11: 8시간 저장량 | G11: 판 수 환산 | H11: 광고 2배 시 판 수 환산
A12: 공원 | B12: 346 | C12: 1 | D12: 0 | E12: =B12*$B$5*(1+$B$6*C12)*(1+$B$7*D12) -> 79.58 | F12: =E12*$B$8 -> 636.64 | G12: =IF(B12>0,F12/B12,0) -> 1.84 | H12: =G12*$B$9 -> 3.68
A13: 도시 옥상 | B13: 1919 | C13: 2 | D13: 2 | E13: =B13*$B$5*(1+$B$6*C13)*(1+$B$7*D13) -> 598.728 | F13: =E13*$B$8 -> 4789.824 | G13: =IF(B13>0,F13/B13,0) -> 2.496 | H13: =G13*$B$9 -> 4.992
A14: 구름 위 | B14: 7903 | C14: 3 | D14: 4 | E14: =B14*$B$5*(1+$B$6*C14)*(1+$B$7*D14) -> 3208.618 | F14: =E14*$B$8 -> 25668.944 | G14: =IF(B14>0,F14/B14,0) -> 3.248 | H14: =G14*$B$9 -> 6.496
A15: 우주 | B15: 24394 | C15: 4 | D15: 6 | E15: =B15*$B$5*(1+$B$6*C15)*(1+$B$7*D15) -> 12489.728 | F15: =E15*$B$8 -> 99917.824 | G15: =IF(B15>0,F15/B15,0) -> 4.096 | H15: =G15*$B$9 -> 8.192
A16: 달 | B16: 84051 | C16: 5 | D16: 8 | E16: =B16*$B$5*(1+$B$6*C16)*(1+$B$7*D16) -> 52952.13 | F16: =E16*$B$8 -> 423617.04 | G16: =IF(B16>0,F16/B16,0) -> 5.04 | H16: =G16*$B$9 -> 10.08
A18: ※ 최고기록 1판 씨앗 = 「진행 시뮬」의 광고X 시나리오에서 해당 구역 첫 도달 판의 씨앗(값). 친구 수·쳇바퀴 Lv는 가정.
A19: → 목표: 8시간 저장량이 초반 약 2판 → 후반 약 5판 분량. 너무 크면 플레이 동기가 줄고, 너무 작으면 재방문 보상이 약함.

Sheet 스테이지
A1: 스테이지 — 목표 거리·별·월드 해금 (GDD §4 스테이지 구조)
A2: A~D·C32·C35~C39 = 입력값(GDD 표와 동일). E~H = tool/balance/pacing_sim.py 생성값(조작 없는 탐욕 구매 시뮬, 「진행 시뮬」과 같은 규칙). 1-1 은 PERFECT 발사로 첫 판 클리어 의도(Lv0 22.96m × 1.15 ≥ 25m).
A4: 월드 | B4: 스테이지 | C4: 목표 거리(m) | D4: 보스 | E4: 도달 판수(광고X, 누적) | F4: 스테이지당 판수(광고X) | G4: 도달 판수(광고100%, 누적) | H4: 스테이지당 판수(광고100%)
A5: 1 | B5: 1 | C5: 25 | E5: 4 | F5: 4 | G5: 3 | H5: 3
A6: 1 | B6: 2 | C6: 80 | E6: 6 | F6: 2 | G6: 5 | H6: 2
A7: 1 | B7: 3 | C7: 150 | E7: 8 | F7: 2 | G7: 6 | H7: 1
A8: 1 | B8: 4 | C8: 280 | E8: 10 | F8: 2 | G8: 7 | H8: 1
A9: 1 | B9: 5 | C9: 500 | D9: 보스 | E9: 13 | F9: 3 | G9: 9 | H9: 2
A10: 2 | B10: 1 | C10: 650 | E10: 14 | F10: 1 | G10: 9 | H10: 0
A11: 2 | B11: 2 | C11: 850 | E11: 15 | F11: 1 | G11: 10 | H11: 1
A12: 2 | B12: 3 | C12: 1100 | E12: 17 | F12: 2 | G12: 11 | H12: 1
A13: 2 | B13: 4 | C13: 1500 | E13: 18 | F13: 1 | G13: 12 | H13: 1
A14: 2 | B14: 5 | C14: 2000 | D14: 보스 | E14: 20 | F14: 2 | G14: 13 | H14: 1
A15: 3 | B15: 1 | C15: 2500 | E15: 22 | F15: 2 | G15: 13 | H15: 0
A16: 3 | B16: 2 | C16: 3100 | E16: 23 | F16: 1 | G16: 14 | H16: 1
A17: 3 | B17: 3 | C17: 3800 | E17: 24 | F17: 1 | G17: 15 | H17: 1
A18: 3 | B18: 4 | C18: 4800 | E18: 27 | F18: 3 | G18: 16 | H18: 1
A19: 3 | B19: 5 | C19: 6000 | D19: 보스 | E19: 29 | F19: 2 | G19: 17 | H19: 1
A20: 4 | B20: 1 | C20: 7200 | E20: 31 | F20: 2 | G20: 18 | H20: 1
A21: 4 | B21: 2 | C21: 8600 | E21: 33 | F21: 2 | G21: 20 | H21: 2
A22: 4 | B22: 3 | C22: 10300 | E22: 37 | F22: 4 | G22: 21 | H22: 1
A23: 4 | B23: 4 | C23: 12500 | E23: 40 | F23: 3 | G23: 23 | H23: 2
A24: 4 | B24: 5 | C24: 15000 | D24: 보스 | E24: 45 | F24: 5 | G24: 26 | H24: 3
A25: 5 | B25: 1 | C25: 18000 | E25: 52 | F25: 7 | G25: 29 | H25: 3
A26: 5 | B26: 2 | C26: 22000 | E26: 59 | F26: 7 | G26: 33 | H26: 4
A27: 5 | B27: 3 | C27: 27000 | E27: 74 | F27: 15 | G27: 40 | H27: 7
A28: 5 | B28: 4 | C28: 33000 | E28: 90 | F28: 16 | G28: 48 | H28: 8
A29: 5 | B29: 5 | C29: 40000 | D29: 보스 | E29: 113 | F29: 23 | G29: 60 | H29: 12
A32: ★★ 목표 배율 | B32: stage_star2_ratio | C32: 1.3 | D32: 목표 거리의 130% 도달 시 별 2개
A34: 월드 해금 | B34: Remote Config 키 | C34: 필요 별 개수 | D34: + 이전 월드 마지막 스테이지 클리어
A35: 2 | B35: world_unlock_stars | C35: 8
A36: 3 | B36: world_unlock_stars | C36: 20
A37: 4 | B37: world_unlock_stars | C37: 32
A38: 5 | B38: world_unlock_stars | C38: 45
A39: 6 | B39: world_unlock_stars | C39: 60
